2025-04-10 09:26:49,540 - app.utils.config_loader - INFO - Успешно загружен F:\замена идпо\RBConverter\conf\connection.json
2025-04-10 09:26:49,540 - app.utils.config_loader - WARNING - Файл configuration.json не найден, используются значения по умолчанию
2025-04-10 09:26:49,540 - root - CRITICAL - Application failed: Не найдена конфигурация API
Traceback (most recent call last):
  File "F:\замена идпо\RBConverter\main.py", line 20, in main
    service = DataProcessingService(config)
  File "F:\замена идпо\RBConverter\app\services\data_service.py", line 18, in __init__
    self._validate_config()
  File "F:\замена идпо\RBConverter\app\services\data_service.py", line 32, in _validate_config
    raise ValueError(error_msg)
ValueError: Не найдена конфигурация API
2025-04-10 09:27:50,105 - app.utils.config_loader - INFO - Успешно загружен F:\замена идпо\RBConverter\conf\connection.json
2025-04-10 09:27:50,105 - app.utils.config_loader - ERROR - Ошибка загрузки configuration.json: Expecting value: line 11 column 22 (char 189)
2025-04-10 09:27:50,106 - root - CRITICAL - Application failed: Не найдена конфигурация API
Traceback (most recent call last):
  File "F:\замена идпо\RBConverter\main.py", line 20, in main
    service = DataProcessingService(config)
  File "F:\замена идпо\RBConverter\app\services\data_service.py", line 18, in __init__
    self._validate_config()
  File "F:\замена идпо\RBConverter\app\services\data_service.py", line 32, in _validate_config
    raise ValueError(error_msg)
ValueError: Не найдена конфигурация API
2025-04-10 09:28:17,275 - app.utils.config_loader - INFO - Успешно загружен F:\замена идпо\RBConverter\conf\connection.json
2025-04-10 09:28:17,276 - app.utils.config_loader - INFO - Успешно загружен F:\замена идпо\RBConverter\conf\configuration.json
2025-04-10 09:28:17,276 - app.services.data_service - ERROR - Ошибка загрузки field_config: [Errno 2] No such file or directory: 'F:\\замена идпо\\RBConverter\\conf\\field_config.json'
2025-04-10 09:28:18,277 - app.core.database - INFO - Успешное подключение к PostgreSQL
2025-04-10 09:28:18,277 - app.core.database - INFO - 2025-02-20 12:00:00
2025-04-10 09:28:18,277 - app.core.database - INFO - Используется start_date: 2025-02-20 12:00:00
2025-04-10 09:28:18,781 - app.core.database - INFO - Найдено нарушений: 1
2025-04-10 09:28:18,781 - app.services.data_service - INFO - Found 1 new violations
2025-04-10 09:28:19,775 - app.core.ftp_client - INFO - FTP подключение установлено
2025-04-10 09:28:27,912 - app.core.ftp_client - INFO - Загружен файл 2308011_2025_04_01_13_18_01_19_00_00.jpg (389290 байт)
2025-04-10 09:28:27,913 - app.services.data_service - ERROR - Failed to process violation 1: DataProcessingService._enrich_data() takes 2 positional arguments but 3 were given
2025-04-10 09:28:27,914 - app.core.database - INFO - Соединение с PostgreSQL закрыто
2025-04-10 09:28:28,166 - app.core.ftp_client - INFO - FTP соединение закрыто
2025-04-10 09:31:35,708 - app.utils.config_loader - INFO - Успешно загружен F:\замена идпо\RBConverter\conf\connection.json
2025-04-10 09:31:35,709 - app.utils.config_loader - INFO - Успешно загружен F:\замена идпо\RBConverter\conf\configuration.json
2025-04-10 09:31:35,709 - app.services.data_service - ERROR - Ошибка загрузки field_config: [Errno 2] No such file or directory: 'F:\\замена идпо\\RBConverter\\conf\\field_config.json'
2025-04-10 09:32:35,760 - app.utils.config_loader - INFO - Успешно загружен F:\замена идпо\RBConverter\conf\connection.json
2025-04-10 09:32:35,761 - app.utils.config_loader - INFO - Успешно загружен F:\замена идпо\RBConverter\conf\configuration.json
2025-04-10 09:32:35,761 - app.services.data_service - ERROR - Ошибка загрузки field_config: [Errno 2] No such file or directory: 'F:\\замена идпо\\RBConverter\\conf\\field_config.json'
2025-04-10 09:32:36,782 - app.core.database - INFO - Успешное подключение к PostgreSQL
2025-04-10 09:32:36,782 - app.core.database - INFO - 2025-02-20 12:00:00
2025-04-10 09:32:36,783 - app.core.database - INFO - Используется start_date: 2025-02-20 12:00:00
2025-04-10 09:32:37,296 - app.core.database - INFO - Найдено нарушений: 1
2025-04-10 09:32:37,296 - app.services.data_service - INFO - Found 1 new violations
2025-04-10 09:32:38,336 - app.core.ftp_client - INFO - FTP подключение установлено
2025-04-10 09:32:47,092 - app.core.ftp_client - INFO - Загружен файл 2308011_2025_04_01_13_18_01_19_00_00.jpg (389290 байт)
2025-04-10 09:32:47,092 - app.services.data_service - ERROR - Failed to process violation 1: DataProcessingService._enrich_data() takes 2 positional arguments but 3 were given
2025-04-10 09:32:47,092 - app.core.database - INFO - Соединение с PostgreSQL закрыто
2025-04-10 09:32:47,348 - app.core.ftp_client - INFO - FTP соединение закрыто
2025-04-10 09:33:09,215 - app.utils.config_loader - INFO - Успешно загружен F:\замена идпо\RBConverter\conf\connection.json
2025-04-10 09:33:09,215 - app.utils.config_loader - INFO - Успешно загружен F:\замена идпо\RBConverter\conf\configuration.json
2025-04-10 09:33:13,824 - app.core.database - INFO - Успешное подключение к PostgreSQL
2025-04-10 09:33:13,824 - app.core.database - INFO - 2025-02-20 12:00:00
2025-04-10 09:33:13,825 - app.core.database - INFO - Используется start_date: 2025-02-20 12:00:00
2025-04-10 09:33:16,014 - app.core.database - INFO - Найдено нарушений: 1
2025-04-10 09:33:16,014 - app.services.data_service - INFO - Found 1 new violations
2025-04-10 09:33:19,663 - app.core.ftp_client - INFO - FTP подключение установлено
2025-04-10 09:33:37,952 - app.core.ftp_client - INFO - Загружен файл 2308011_2025_04_01_13_18_01_19_00_00.jpg (389290 байт)
2025-04-10 09:33:37,953 - app.services.data_service - ERROR - Failed to process violation 1: DataProcessingService._enrich_data() takes 2 positional arguments but 3 were given
2025-04-10 09:33:37,953 - app.core.database - INFO - Соединение с PostgreSQL закрыто
2025-04-10 09:33:39,414 - app.core.ftp_client - INFO - FTP соединение закрыто
2025-04-10 09:34:32,024 - app.utils.config_loader - INFO - Успешно загружен F:\замена идпо\RBConverter\conf\connection.json
2025-04-10 09:34:32,025 - app.utils.config_loader - INFO - Успешно загружен F:\замена идпо\RBConverter\conf\configuration.json
2025-04-10 09:34:40,183 - app.core.database - INFO - Успешное подключение к PostgreSQL
2025-04-10 09:34:40,183 - app.core.database - INFO - 2025-02-20 12:00:00
2025-04-10 09:34:40,183 - app.core.database - INFO - Используется start_date: 2025-02-20 12:00:00
2025-04-10 09:34:40,758 - app.core.database - INFO - Найдено нарушений: 1
2025-04-10 09:34:40,759 - app.services.data_service - INFO - Found 1 new violations
2025-04-10 09:34:41,894 - app.core.ftp_client - INFO - FTP подключение установлено
2025-04-10 09:34:51,066 - app.core.ftp_client - INFO - Загружен файл 2308011_2025_04_01_13_18_01_19_00_00.jpg (389290 байт)
2025-04-10 09:34:51,067 - app.services.data_service - ERROR - Failed to process violation 1: DataProcessingService._enrich_data() takes 2 positional arguments but 3 were given
2025-04-10 09:34:51,067 - app.core.database - INFO - Соединение с PostgreSQL закрыто
2025-04-10 09:34:52,385 - app.core.ftp_client - INFO - FTP соединение закрыто
2025-04-10 09:38:39,820 - app.utils.config_loader - INFO - Успешно загружен F:\замена идпо\RBConverter\conf\connection.json
2025-04-10 09:38:39,821 - app.utils.config_loader - INFO - Успешно загружен F:\замена идпо\RBConverter\conf\configuration.json
2025-04-10 09:38:41,938 - app.core.database - INFO - Успешное подключение к PostgreSQL
2025-04-10 09:38:41,938 - app.core.database - INFO - 2025-02-20 12:00:00
2025-04-10 09:38:41,939 - app.core.database - INFO - Используется start_date: 2025-02-20 12:00:00
2025-04-10 09:38:42,501 - app.core.database - INFO - Найдено нарушений: 1
2025-04-10 09:38:42,502 - __main__ - INFO - Найдено 1 новых нарушений для обработки
2025-04-10 09:38:42,502 - __main__ - INFO - Обработка нарушения 1 (файл: /mnt/targets/ftp/all_fixations/2025/04/01/2308011_2025_04_01_13_18_01_19_00_00.jpg)
2025-04-10 09:38:43,816 - app.core.ftp_client - INFO - FTP подключение установлено
2025-04-10 09:39:14,368 - app.core.ftp_client - ERROR - Ошибка загрузки файла: timed out
Traceback (most recent call last):
  File "F:\замена идпо\RBConverter\app\core\ftp_client.py", line 55, in download
    if filename not in self.connection.nlst():
  File "C:\Users\user\AppData\Local\Programs\Python\Python310\lib\ftplib.py", line 553, in nlst
    self.retrlines(cmd, files.append)
  File "C:\Users\user\AppData\Local\Programs\Python\Python310\lib\ftplib.py", line 462, in retrlines
    with self.transfercmd(cmd) as conn, \
  File "C:\Users\user\AppData\Local\Programs\Python\Python310\lib\ftplib.py", line 393, in transfercmd
    return self.ntransfercmd(cmd, rest)[0]
  File "C:\Users\user\AppData\Local\Programs\Python\Python310\lib\ftplib.py", line 353, in ntransfercmd
    host, port = self.makepasv()
  File "C:\Users\user\AppData\Local\Programs\Python\Python310\lib\ftplib.py", line 327, in makepasv
    untrusted_host, port = parse227(self.sendcmd('PASV'))
  File "C:\Users\user\AppData\Local\Programs\Python\Python310\lib\ftplib.py", line 281, in sendcmd
    return self.getresp()
  File "C:\Users\user\AppData\Local\Programs\Python\Python310\lib\ftplib.py", line 244, in getresp
    resp = self.getmultiline()
  File "C:\Users\user\AppData\Local\Programs\Python\Python310\lib\ftplib.py", line 230, in getmultiline
    line = self.getline()
  File "C:\Users\user\AppData\Local\Programs\Python\Python310\lib\ftplib.py", line 212, in getline
    line = self.file.readline(self.maxline + 1)
  File "C:\Users\user\AppData\Local\Programs\Python\Python310\lib\socket.py", line 705, in readinto
    return self._sock.recv_into(b)
TimeoutError: timed out
2025-04-10 09:39:14,410 - __main__ - ERROR - Не удалось загрузить файл /mnt/targets/ftp/all_fixations/2025/04/01/2308011_2025_04_01_13_18_01_19_00_00.jpg
2025-04-10 09:39:14,410 - __main__ - INFO - Обновлена дата последней обработки: 2025-04-10 09:39:14
2025-04-10 09:39:14,410 - app.core.database - INFO - Соединение с PostgreSQL закрыто
2025-04-10 09:39:14,411 - app.core.ftp_client - WARNING - Ошибка при закрытии FTP: cannot read from timed out object
2025-04-10 09:39:53,636 - app.utils.config_loader - INFO - Успешно загружен F:\замена идпо\RBConverter\conf\connection.json
2025-04-10 09:39:53,637 - app.utils.config_loader - INFO - Успешно загружен F:\замена идпо\RBConverter\conf\configuration.json
2025-04-10 09:39:53,675 - app.core.database - INFO - Успешное подключение к PostgreSQL
2025-04-10 09:39:53,676 - app.core.database - INFO - 2025-02-20 12:00:00
2025-04-10 09:39:53,676 - app.core.database - INFO - Используется start_date: 2025-02-20 12:00:00
2025-04-10 09:39:53,691 - app.core.database - INFO - Найдено нарушений: 1
2025-04-10 09:39:53,691 - __main__ - INFO - Найдено 1 новых нарушений для обработки
2025-04-10 09:39:53,691 - __main__ - INFO - Обработка нарушения 145254 (файл: /mnt/targets/ftp/all_fixations/2025/02/20/2309033_2025_02_20_12_20_17_20_04_00.jpg)
2025-04-10 09:39:53,743 - app.core.ftp_client - INFO - FTP подключение установлено
2025-04-10 09:39:53,966 - app.core.ftp_client - INFO - Загружен файл 2309033_2025_02_20_12_20_17_20_04_00.jpg (1662933 байт)
2025-04-10 09:39:53,966 - app.services.api_service - ERROR - File error: File /mnt/targets/ftp/all_fixations/2025/02/20/2309033_2025_02_20_12_20_17_20_04_00.jpg not found
2025-04-10 09:39:53,967 - __main__ - ERROR - Ошибка при отправке нарушения 145254
2025-04-10 09:39:53,967 - __main__ - INFO - Обновлена дата последней обработки: 2025-04-10 09:39:53
2025-04-10 09:39:53,967 - app.core.database - INFO - Соединение с PostgreSQL закрыто
2025-04-10 09:39:53,969 - app.core.ftp_client - INFO - FTP соединение закрыто
2025-04-10 09:39:54,831 - app.utils.config_loader - INFO - Успешно загружен F:\замена идпо\RBConverter\conf\connection.json
2025-04-10 09:39:54,831 - app.utils.config_loader - INFO - Успешно загружен F:\замена идпо\RBConverter\conf\configuration.json
2025-04-10 09:39:54,874 - app.core.database - INFO - Успешное подключение к PostgreSQL
2025-04-10 09:39:54,874 - app.core.database - INFO - 2025-02-20 12:00:00
2025-04-10 09:39:54,874 - app.core.database - INFO - Используется start_date: 2025-02-20 12:00:00
2025-04-10 09:39:54,910 - app.core.database - INFO - Найдено нарушений: 1
2025-04-10 09:39:54,910 - __main__ - INFO - Найдено 1 новых нарушений для обработки
2025-04-10 09:39:54,910 - __main__ - INFO - Обработка нарушения 145254 (файл: /mnt/targets/ftp/all_fixations/2025/02/20/2309033_2025_02_20_12_20_17_20_04_00.jpg)
2025-04-10 09:39:54,953 - app.core.ftp_client - INFO - FTP подключение установлено
2025-04-10 09:39:55,157 - app.core.ftp_client - INFO - Загружен файл 2309033_2025_02_20_12_20_17_20_04_00.jpg (1662933 байт)
2025-04-10 09:39:55,157 - app.services.api_service - ERROR - File error: File /mnt/targets/ftp/all_fixations/2025/02/20/2309033_2025_02_20_12_20_17_20_04_00.jpg not found
2025-04-10 09:39:55,158 - __main__ - ERROR - Ошибка при отправке нарушения 145254
2025-04-10 09:39:55,158 - __main__ - INFO - Обновлена дата последней обработки: 2025-04-10 09:39:55
2025-04-10 09:39:55,158 - app.core.database - INFO - Соединение с PostgreSQL закрыто
2025-04-10 09:39:55,162 - app.core.ftp_client - INFO - FTP соединение закрыто
2025-04-10 09:39:58,078 - app.utils.config_loader - INFO - Успешно загружен F:\замена идпо\RBConverter\conf\connection.json
2025-04-10 09:39:58,079 - app.utils.config_loader - INFO - Успешно загружен F:\замена идпо\RBConverter\conf\configuration.json
2025-04-10 09:39:58,122 - app.core.database - INFO - Успешное подключение к PostgreSQL
2025-04-10 09:39:58,123 - app.core.database - INFO - 2025-02-20 12:00:00
2025-04-10 09:39:58,123 - app.core.database - INFO - Используется start_date: 2025-02-20 12:00:00
2025-04-10 09:39:58,138 - app.core.database - INFO - Найдено нарушений: 1
2025-04-10 09:39:58,138 - __main__ - INFO - Найдено 1 новых нарушений для обработки
2025-04-10 09:39:58,138 - __main__ - INFO - Обработка нарушения 145254 (файл: /mnt/targets/ftp/all_fixations/2025/02/20/2309033_2025_02_20_12_20_17_20_04_00.jpg)
2025-04-10 09:39:58,184 - app.core.ftp_client - INFO - FTP подключение установлено
2025-04-10 09:39:58,371 - app.core.ftp_client - INFO - Загружен файл 2309033_2025_02_20_12_20_17_20_04_00.jpg (1662933 байт)
2025-04-10 09:39:58,372 - app.services.api_service - ERROR - File error: File /mnt/targets/ftp/all_fixations/2025/02/20/2309033_2025_02_20_12_20_17_20_04_00.jpg not found
2025-04-10 09:39:58,372 - __main__ - ERROR - Ошибка при отправке нарушения 145254
2025-04-10 09:39:58,372 - __main__ - INFO - Обновлена дата последней обработки: 2025-04-10 09:39:58
2025-04-10 09:39:58,372 - app.core.database - INFO - Соединение с PostgreSQL закрыто
2025-04-10 09:39:58,374 - app.core.ftp_client - INFO - FTP соединение закрыто
2025-04-10 09:40:27,172 - app.utils.config_loader - INFO - Успешно загружен F:\замена идпо\RBConverter\conf\connection.json
2025-04-10 09:40:27,172 - app.utils.config_loader - INFO - Успешно загружен F:\замена идпо\RBConverter\conf\configuration.json
2025-04-10 09:40:27,212 - app.core.database - INFO - Успешное подключение к PostgreSQL
2025-04-10 09:40:27,213 - app.core.database - INFO - 2025-02-19 12:00:00
2025-04-10 09:40:27,213 - app.core.database - INFO - Используется start_date: 2025-02-19 12:00:00
2025-04-10 09:40:27,235 - app.core.database - INFO - Найдено нарушений: 1
2025-04-10 09:40:27,235 - __main__ - INFO - Найдено 1 новых нарушений для обработки
2025-04-10 09:40:27,235 - __main__ - INFO - Обработка нарушения 145146 (файл: /mnt/targets/ftp/all_fixations/2025/02/19/2309033_2025_02_19_12_26_42_30_04_00.jpg)
2025-04-10 09:40:27,278 - app.core.ftp_client - INFO - FTP подключение установлено
2025-04-10 09:40:27,479 - app.core.ftp_client - INFO - Загружен файл 2309033_2025_02_19_12_26_42_30_04_00.jpg (1689417 байт)
2025-04-10 09:40:27,480 - app.services.api_service - ERROR - File error: File /mnt/targets/ftp/all_fixations/2025/02/19/2309033_2025_02_19_12_26_42_30_04_00.jpg not found
2025-04-10 09:40:27,480 - __main__ - ERROR - Ошибка при отправке нарушения 145146
2025-04-10 09:40:27,480 - __main__ - INFO - Обновлена дата последней обработки: 2025-04-10 09:40:27
2025-04-10 09:40:27,481 - app.core.database - INFO - Соединение с PostgreSQL закрыто
2025-04-10 09:40:27,483 - app.core.ftp_client - INFO - FTP соединение закрыто
2025-04-10 09:42:01,920 - app.utils.config_loader - INFO - Успешно загружен F:\замена идпо\RBConverter\conf\connection.json
2025-04-10 09:42:01,921 - app.utils.config_loader - INFO - Успешно загружен F:\замена идпо\RBConverter\conf\configuration.json
2025-04-10 09:42:01,961 - app.core.database - INFO - Успешное подключение к PostgreSQL
2025-04-10 09:42:01,961 - app.core.database - INFO - 2025-02-19 12:00:00
2025-04-10 09:42:01,961 - app.core.database - INFO - Используется start_date: 2025-02-19 12:00:00
2025-04-10 09:42:01,976 - app.core.database - INFO - Найдено нарушений: 1
2025-04-10 09:42:01,976 - __main__ - INFO - Найдено 1 новых нарушений для обработки
2025-04-10 09:42:01,976 - __main__ - INFO - Обработка нарушения 145146 (файл: /mnt/targets/ftp/all_fixations/2025/02/19/2309033_2025_02_19_12_26_42_30_04_00.jpg)
2025-04-10 09:42:02,018 - app.core.ftp_client - INFO - FTP подключение установлено
2025-04-10 09:42:02,230 - app.core.ftp_client - INFO - Загружен файл 2309033_2025_02_19_12_26_42_30_04_00.jpg (1689417 байт)
2025-04-10 09:42:02,230 - app.services.api_service - ERROR - File error: File /mnt/targets/ftp/all_fixations/2025/02/19/2309033_2025_02_19_12_26_42_30_04_00.jpg not found
2025-04-10 09:42:02,230 - __main__ - ERROR - Ошибка при отправке нарушения 145146
2025-04-10 09:42:02,231 - __main__ - INFO - Обновлена дата последней обработки: 2025-04-10 09:42:02
2025-04-10 09:42:02,231 - app.core.database - INFO - Соединение с PostgreSQL закрыто
2025-04-10 09:42:02,232 - app.core.ftp_client - INFO - FTP соединение закрыто
2025-04-10 09:44:03,149 - app.utils.config_loader - INFO - Успешно загружен F:\замена идпо\RBConverter\conf\connection.json
2025-04-10 09:44:03,150 - app.utils.config_loader - INFO - Успешно загружен F:\замена идпо\RBConverter\conf\configuration.json
2025-04-10 09:44:03,187 - app.core.database - INFO - Успешное подключение к PostgreSQL
2025-04-10 09:44:03,187 - app.core.database - INFO - 2025-02-19 12:00:00
2025-04-10 09:44:03,187 - app.core.database - INFO - Используется start_date: 2025-02-19 12:00:00
2025-04-10 09:44:03,207 - app.core.database - INFO - Найдено нарушений: 1
2025-04-10 09:44:03,208 - __main__ - INFO - Найдено 1 новых нарушений для обработки
2025-04-10 09:44:03,208 - __main__ - INFO - Обработка нарушения 145146 (файл: /mnt/targets/ftp/all_fixations/2025/02/19/2309033_2025_02_19_12_26_42_30_04_00.jpg)
2025-04-10 09:44:03,250 - app.core.ftp_client - INFO - FTP подключение установлено
2025-04-10 09:44:03,664 - app.core.ftp_client - INFO - Загружен файл 2309033_2025_02_19_12_26_42_30_04_00.jpg (1689417 байт)
2025-04-10 09:44:03,665 - __main__ - ERROR - Ошибка при обработке нарушения 145146: 'SendToServer' object has no attribute 'send_violation'
Traceback (most recent call last):
  File "F:\замена идпо\RBConverter\main.py", line 74, in _process_single_violation
    success = self.api.send_violation(
AttributeError: 'SendToServer' object has no attribute 'send_violation'
2025-04-10 09:44:03,668 - __main__ - INFO - Обновлена дата последней обработки: 2025-04-10 09:44:03
2025-04-10 09:44:03,668 - app.core.database - INFO - Соединение с PostgreSQL закрыто
2025-04-10 09:44:03,670 - app.core.ftp_client - INFO - FTP соединение закрыто
2025-04-10 09:44:20,926 - app.utils.config_loader - INFO - Успешно загружен F:\замена идпо\RBConverter\conf\connection.json
2025-04-10 09:44:20,927 - app.utils.config_loader - INFO - Успешно загружен F:\замена идпо\RBConverter\conf\configuration.json
2025-04-10 09:44:20,967 - app.core.database - INFO - Успешное подключение к PostgreSQL
2025-04-10 09:44:20,967 - app.core.database - INFO - 2025-02-19 12:00:00
2025-04-10 09:44:20,968 - app.core.database - INFO - Используется start_date: 2025-02-19 12:00:00
2025-04-10 09:44:20,990 - app.core.database - INFO - Найдено нарушений: 1
2025-04-10 09:44:20,990 - __main__ - INFO - Найдено 1 новых нарушений для обработки
2025-04-10 09:44:20,990 - __main__ - INFO - Обработка нарушения 145146 (файл: /mnt/targets/ftp/all_fixations/2025/02/19/2309033_2025_02_19_12_26_42_30_04_00.jpg)
2025-04-10 09:44:21,032 - app.core.ftp_client - INFO - FTP подключение установлено
2025-04-10 09:44:21,212 - app.core.ftp_client - INFO - Загружен файл 2309033_2025_02_19_12_26_42_30_04_00.jpg (1689417 байт)
2025-04-10 09:44:21,502 - app.services.api_service - ERROR - Server error 413: Unknown error
Status: 413
Headers: {'Content-Length': '0', 'Date': 'Thu, 10 Apr 2025 06:44:21 GMT', 'Connection': 'close'}
Body: {
  "raw_response": ""
}
2025-04-10 09:44:21,503 - __main__ - ERROR - Ошибка при отправке нарушения 145146
2025-04-10 09:44:21,504 - __main__ - INFO - Обновлена дата последней обработки: 2025-04-10 09:44:21
2025-04-10 09:44:21,504 - app.core.database - INFO - Соединение с PostgreSQL закрыто
2025-04-10 09:44:21,506 - app.core.ftp_client - INFO - FTP соединение закрыто
2025-04-10 09:45:21,119 - app.utils.config_loader - INFO - Успешно загружен F:\замена идпо\RBConverter\conf\connection.json
2025-04-10 09:45:21,119 - app.utils.config_loader - INFO - Успешно загружен F:\замена идпо\RBConverter\conf\configuration.json
2025-04-10 09:45:21,167 - app.core.database - INFO - Успешное подключение к PostgreSQL
2025-04-10 09:45:21,167 - app.core.database - INFO - 2025-02-19 12:00:00
2025-04-10 09:45:21,167 - app.core.database - INFO - Используется start_date: 2025-02-19 12:00:00
2025-04-10 09:45:21,179 - app.core.database - INFO - Найдено нарушений: 1
2025-04-10 09:45:21,180 - __main__ - INFO - Найдено 1 новых нарушений для обработки
2025-04-10 09:45:21,180 - __main__ - INFO - Обработка нарушения 145146 (файл: /mnt/targets/ftp/all_fixations/2025/02/19/2309033_2025_02_19_12_26_42_30_04_00.jpg)
2025-04-10 09:45:21,218 - app.core.ftp_client - INFO - FTP подключение установлено
2025-04-10 09:45:21,417 - app.core.ftp_client - INFO - Загружен файл 2309033_2025_02_19_12_26_42_30_04_00.jpg (1689417 байт)
2025-04-10 09:45:21,492 - app.services.api_service - ERROR - Server error 413: Unknown error
Status: 413
Headers: {'Content-Length': '0', 'Date': 'Thu, 10 Apr 2025 06:45:21 GMT', 'Connection': 'close'}
Body: {
  "raw_response": ""
}
2025-04-10 09:45:21,493 - __main__ - ERROR - Ошибка при отправке нарушения 145146
2025-04-10 09:45:21,494 - __main__ - INFO - Обновлена дата последней обработки: 2025-04-10 09:45:21
2025-04-10 09:45:21,494 - app.core.database - INFO - Соединение с PostgreSQL закрыто
2025-04-10 09:45:21,498 - app.core.ftp_client - INFO - FTP соединение закрыто
2025-04-10 09:45:54,286 - app.utils.config_loader - INFO - Успешно загружен F:\замена идпо\RBConverter\conf\connection.json
2025-04-10 09:45:54,286 - app.utils.config_loader - INFO - Успешно загружен F:\замена идпо\RBConverter\conf\configuration.json
2025-04-10 09:45:54,332 - app.core.database - INFO - Успешное подключение к PostgreSQL
2025-04-10 09:45:54,332 - app.core.database - INFO - 2025-02-19 12:00:00
2025-04-10 09:45:54,333 - app.core.database - INFO - Используется start_date: 2025-02-19 12:00:00
2025-04-10 09:45:54,356 - app.core.database - INFO - Найдено нарушений: 1
2025-04-10 09:45:54,356 - __main__ - INFO - Найдено 1 новых нарушений для обработки
2025-04-10 09:45:54,356 - __main__ - INFO - Обработка нарушения 145146 (файл: /mnt/targets/ftp/all_fixations/2025/02/19/2309033_2025_02_19_12_26_42_30_04_00.jpg)
2025-04-10 09:45:54,393 - app.core.ftp_client - INFO - FTP подключение установлено
2025-04-10 09:45:54,602 - app.core.ftp_client - INFO - Загружен файл 2309033_2025_02_19_12_26_42_30_04_00.jpg (1689417 байт)
2025-04-10 09:45:54,665 - app.services.api_service - ERROR - Server error 413: Unknown error
Status: 413
Headers: {'Content-Length': '0', 'Date': 'Thu, 10 Apr 2025 06:45:54 GMT', 'Connection': 'close'}
Body: {
  "raw_response": ""
}
2025-04-10 09:45:54,665 - __main__ - ERROR - Ошибка при отправке нарушения 145146
2025-04-10 09:45:54,667 - __main__ - INFO - Обновлена дата последней обработки: 2025-04-10 09:45:54
2025-04-10 09:45:54,667 - app.core.database - INFO - Соединение с PostgreSQL закрыто
2025-04-10 09:45:54,669 - app.core.ftp_client - INFO - FTP соединение закрыто
2025-04-10 09:49:29,745 - app.utils.config_loader - INFO - Успешно загружен F:\замена идпо\RBConverter\conf\connection.json
2025-04-10 09:49:29,745 - app.utils.config_loader - INFO - Успешно загружен F:\замена идпо\RBConverter\conf\configuration.json
2025-04-10 09:49:29,782 - app.core.database - INFO - Успешное подключение к PostgreSQL
2025-04-10 09:49:29,783 - app.core.database - INFO - 2025-02-19 12:00:00
2025-04-10 09:49:29,783 - app.core.database - INFO - Используется start_date: 2025-02-19 12:00:00
2025-04-10 09:49:29,814 - app.core.database - INFO - Найдено нарушений: 1
2025-04-10 09:49:29,814 - __main__ - INFO - Найдено 1 новых нарушений для обработки
2025-04-10 09:49:29,814 - __main__ - INFO - Обработка нарушения 145146 (файл: /mnt/targets/ftp/all_fixations/2025/02/19/2309033_2025_02_19_12_26_42_30_04_00.jpg)
2025-04-10 09:49:29,861 - app.core.ftp_client - INFO - FTP подключение установлено
2025-04-10 09:49:30,051 - app.core.ftp_client - INFO - Загружен файл 2309033_2025_02_19_12_26_42_30_04_00.jpg (1689417 байт)
2025-04-10 09:49:30,106 - app.services.api_service - ERROR - Server error 413: Unknown error
Status: 413
Headers: {'Content-Length': '0', 'Date': 'Thu, 10 Apr 2025 06:49:30 GMT', 'Connection': 'close'}
Body: {
  "raw_response": ""
}
2025-04-10 09:49:30,106 - __main__ - ERROR - Ошибка при отправке нарушения 145146
2025-04-10 09:49:30,107 - __main__ - INFO - Обновлена дата последней обработки: 2025-04-10 09:49:30
2025-04-10 09:49:30,107 - app.core.database - INFO - Соединение с PostgreSQL закрыто
2025-04-10 09:49:30,109 - app.core.ftp_client - INFO - FTP соединение закрыто
2025-04-10 10:13:40,398 - app.utils.config_loader - INFO - Успешно загружен F:\замена идпо\RBConverter\conf\connection.json
2025-04-10 10:13:40,398 - app.utils.config_loader - INFO - Успешно загружен F:\замена идпо\RBConverter\conf\configuration.json
2025-04-10 10:13:40,443 - app.core.database - INFO - Успешное подключение к PostgreSQL
2025-04-10 10:13:40,443 - app.core.database - INFO - 2025-02-19 12:00:00
2025-04-10 10:13:40,443 - app.core.database - INFO - Используется start_date: 2025-02-19 12:00:00
2025-04-10 10:13:40,471 - app.core.database - INFO - Найдено нарушений: 1
2025-04-10 10:13:40,472 - __main__ - INFO - Найдено 1 новых нарушений для обработки
2025-04-10 10:13:40,472 - __main__ - INFO - Обработка нарушения 145146 (файл: /mnt/targets/ftp/all_fixations/2025/02/19/2309033_2025_02_19_12_26_42_30_04_00.jpg)
2025-04-10 10:13:40,518 - app.core.ftp_client - INFO - FTP подключение установлено
2025-04-10 10:13:40,729 - app.core.ftp_client - INFO - Загружен файл 2309033_2025_02_19_12_26_42_30_04_00.jpg (1689417 байт)
2025-04-10 10:13:40,779 - app.services.api_service - ERROR - Server error 413: Unknown error
Status: 413
Headers: {'Content-Length': '0', 'Date': 'Thu, 10 Apr 2025 07:13:40 GMT', 'Connection': 'close'}
Body: {
  "raw_response": ""
}
2025-04-10 10:13:40,779 - __main__ - ERROR - Ошибка при отправке нарушения 145146
2025-04-10 10:13:40,781 - __main__ - INFO - Обновлена дата последней обработки: 2025-04-10 10:13:40
2025-04-10 10:13:40,781 - app.core.database - INFO - Соединение с PostgreSQL закрыто
2025-04-10 10:13:40,782 - app.core.ftp_client - INFO - FTP соединение закрыто
2025-04-10 10:14:05,346 - app.utils.config_loader - INFO - Успешно загружен F:\замена идпо\RBConverter\conf\connection.json
2025-04-10 10:14:05,346 - app.utils.config_loader - INFO - Успешно загружен F:\замена идпо\RBConverter\conf\configuration.json
2025-04-10 10:14:05,392 - app.core.database - INFO - Успешное подключение к PostgreSQL
2025-04-10 10:14:05,392 - app.core.database - INFO - 2025-02-19 12:00:00
2025-04-10 10:14:05,393 - app.core.database - INFO - Используется start_date: 2025-02-19 12:00:00
2025-04-10 10:14:05,416 - app.core.database - INFO - Найдено нарушений: 1
2025-04-10 10:14:05,417 - __main__ - INFO - Найдено 1 новых нарушений для обработки
2025-04-10 10:14:05,417 - __main__ - INFO - Обработка нарушения 145146 (файл: /mnt/targets/ftp/all_fixations/2025/02/19/2309033_2025_02_19_12_26_42_30_04_00.jpg)
2025-04-10 10:14:05,462 - app.core.ftp_client - INFO - FTP подключение установлено
2025-04-10 10:14:05,646 - app.core.ftp_client - INFO - Загружен файл 2309033_2025_02_19_12_26_42_30_04_00.jpg (1689417 байт)
2025-04-10 10:14:05,716 - app.services.api_service - ERROR - Server error 413: Unknown error
Status: 413
Headers: {'Content-Length': '0', 'Date': 'Thu, 10 Apr 2025 07:14:05 GMT', 'Connection': 'close'}
Body: {
  "raw_response": ""
}
2025-04-10 10:14:05,717 - __main__ - ERROR - Ошибка при отправке нарушения 145146
2025-04-10 10:14:05,718 - __main__ - INFO - Обновлена дата последней обработки: 2025-04-10 10:14:05
2025-04-10 10:14:05,718 - app.core.database - INFO - Соединение с PostgreSQL закрыто
2025-04-10 10:14:05,721 - app.core.ftp_client - INFO - FTP соединение закрыто
2025-04-10 10:14:35,406 - app.utils.config_loader - INFO - Успешно загружен F:\замена идпо\RBConverter\conf\connection.json
2025-04-10 10:14:35,406 - app.utils.config_loader - INFO - Успешно загружен F:\замена идпо\RBConverter\conf\configuration.json
2025-04-10 10:14:35,452 - app.core.database - INFO - Успешное подключение к PostgreSQL
2025-04-10 10:14:35,452 - app.core.database - INFO - 2025-02-19 12:00:00
2025-04-10 10:14:35,452 - app.core.database - INFO - Используется start_date: 2025-02-19 12:00:00
2025-04-10 10:14:35,491 - app.core.database - INFO - Найдено нарушений: 1
2025-04-10 10:14:35,491 - __main__ - INFO - Найдено 1 новых нарушений для обработки
2025-04-10 10:14:35,491 - __main__ - INFO - Обработка нарушения 145146 (файл: /mnt/targets/ftp/all_fixations/2025/02/19/2309033_2025_02_19_12_26_42_30_04_00.jpg)
2025-04-10 10:14:35,536 - app.core.ftp_client - INFO - FTP подключение установлено
2025-04-10 10:14:35,745 - app.core.ftp_client - INFO - Загружен файл 2309033_2025_02_19_12_26_42_30_04_00.jpg (1689417 байт)
2025-04-10 10:14:36,104 - app.services.api_service - ERROR - Server error 400: Bad Request
Status: 400
Headers: {'Content-Type': 'application/json', 'Transfer-Encoding': 'chunked', 'Date': 'Thu, 10 Apr 2025 07:14:36 GMT', 'Connection': 'close'}
Body: {
  "timestamp": "2025-04-10T07:14:36.028+00:00",
  "status": 400,
  "error": "Bad Request",
  "path": "/send"
}
2025-04-10 10:14:36,105 - __main__ - ERROR - Ошибка при отправке нарушения 145146
2025-04-10 10:14:36,106 - __main__ - INFO - Обновлена дата последней обработки: 2025-04-10 10:14:36
2025-04-10 10:14:36,107 - app.core.database - INFO - Соединение с PostgreSQL закрыто
2025-04-10 10:14:36,111 - app.core.ftp_client - INFO - FTP соединение закрыто
2025-04-10 10:14:51,265 - app.utils.config_loader - INFO - Успешно загружен F:\замена идпо\RBConverter\conf\connection.json
2025-04-10 10:14:51,265 - app.utils.config_loader - INFO - Успешно загружен F:\замена идпо\RBConverter\conf\configuration.json
2025-04-10 10:14:51,308 - app.core.database - INFO - Успешное подключение к PostgreSQL
2025-04-10 10:14:51,309 - app.core.database - INFO - 2025-02-19 12:00:00
2025-04-10 10:14:51,309 - app.core.database - INFO - Используется start_date: 2025-02-19 12:00:00
2025-04-10 10:14:51,336 - app.core.database - INFO - Найдено нарушений: 1
2025-04-10 10:14:51,336 - __main__ - INFO - Найдено 1 новых нарушений для обработки
2025-04-10 10:14:51,337 - __main__ - INFO - Обработка нарушения 145146 (файл: /mnt/targets/ftp/all_fixations/2025/02/19/2309033_2025_02_19_12_26_42_30_04_00.jpg)
2025-04-10 10:14:51,379 - app.core.ftp_client - INFO - FTP подключение установлено
2025-04-10 10:14:51,595 - app.core.ftp_client - INFO - Загружен файл 2309033_2025_02_19_12_26_42_30_04_00.jpg (1689417 байт)
2025-04-10 10:14:51,634 - app.services.api_service - ERROR - Server error 400: Bad Request
Status: 400
Headers: {'Content-Type': 'application/json', 'Transfer-Encoding': 'chunked', 'Date': 'Thu, 10 Apr 2025 07:14:51 GMT', 'Connection': 'close'}
Body: {
  "timestamp": "2025-04-10T07:14:51.632+00:00",
  "status": 400,
  "error": "Bad Request",
  "path": "/send"
}
2025-04-10 10:14:51,634 - __main__ - ERROR - Ошибка при отправке нарушения 145146
2025-04-10 10:14:51,635 - __main__ - INFO - Обновлена дата последней обработки: 2025-04-10 10:14:51
2025-04-10 10:14:51,635 - app.core.database - INFO - Соединение с PostgreSQL закрыто
2025-04-10 10:14:51,638 - app.core.ftp_client - INFO - FTP соединение закрыто
2025-04-10 10:15:19,919 - app.utils.config_loader - INFO - Успешно загружен F:\замена идпо\RBConverter\conf\connection.json
2025-04-10 10:15:19,919 - app.utils.config_loader - INFO - Успешно загружен F:\замена идпо\RBConverter\conf\configuration.json
2025-04-10 10:15:19,960 - app.core.database - INFO - Успешное подключение к PostgreSQL
2025-04-10 10:15:19,960 - app.core.database - INFO - 2025-02-19 12:00:00
2025-04-10 10:15:19,961 - app.core.database - INFO - Используется start_date: 2025-02-19 12:00:00
2025-04-10 10:15:19,979 - app.core.database - INFO - Найдено нарушений: 1
2025-04-10 10:15:19,979 - __main__ - INFO - Найдено 1 новых нарушений для обработки
2025-04-10 10:15:19,979 - __main__ - INFO - Обработка нарушения 145146 (файл: /mnt/targets/ftp/all_fixations/2025/02/19/2309033_2025_02_19_12_26_42_30_04_00.jpg)
2025-04-10 10:15:20,020 - app.core.ftp_client - INFO - FTP подключение установлено
2025-04-10 10:15:20,224 - app.core.ftp_client - INFO - Загружен файл 2309033_2025_02_19_12_26_42_30_04_00.jpg (1689417 байт)
2025-04-10 10:15:20,245 - app.services.api_service - ERROR - Server error 400: Bad Request
Status: 400
Headers: {'Content-Type': 'application/json', 'Transfer-Encoding': 'chunked', 'Date': 'Thu, 10 Apr 2025 07:15:20 GMT', 'Connection': 'close'}
Body: {
  "timestamp": "2025-04-10T07:15:20.242+00:00",
  "status": 400,
  "error": "Bad Request",
  "path": "/send"
}
2025-04-10 10:15:20,246 - __main__ - ERROR - Ошибка при отправке нарушения 145146
2025-04-10 10:15:20,246 - __main__ - WARNING - Не удалось удалить временный файл: name 'tmp_file_path' is not defined
2025-04-10 10:15:20,246 - __main__ - INFO - Обновлена дата последней обработки: 2025-04-10 10:15:20
2025-04-10 10:15:20,246 - app.core.database - INFO - Соединение с PostgreSQL закрыто
2025-04-10 10:15:20,248 - app.core.ftp_client - INFO - FTP соединение закрыто
2025-04-10 10:19:00,486 - app.utils.config_loader - INFO - Успешно загружен F:\замена идпо\RBConverter\conf\connection.json
2025-04-10 10:19:00,486 - app.utils.config_loader - INFO - Успешно загружен F:\замена идпо\RBConverter\conf\configuration.json
2025-04-10 10:19:00,539 - app.core.database - INFO - Успешное подключение к PostgreSQL
2025-04-10 10:19:00,539 - app.core.database - INFO - 2025-02-19 12:00:00
2025-04-10 10:19:00,539 - app.core.database - INFO - Используется start_date: 2025-02-19 12:00:00
2025-04-10 10:19:00,555 - app.core.database - INFO - Найдено нарушений: 1
2025-04-10 10:19:00,555 - __main__ - INFO - Найдено 1 новых нарушений для обработки
2025-04-10 10:19:00,556 - __main__ - INFO - Обработка нарушения 145146 (файл: /mnt/targets/ftp/all_fixations/2025/02/19/2309033_2025_02_19_12_26_42_30_04_00.jpg)
2025-04-10 10:19:00,600 - app.core.ftp_client - INFO - FTP подключение установлено
2025-04-10 10:19:00,918 - app.core.ftp_client - INFO - Загружен файл 2309033_2025_02_19_12_26_42_30_04_00.jpg (1689417 байт)
2025-04-10 10:19:00,944 - app.services.api_service - ERROR - Server error 400: Bad Request
Status: 400
Headers: {'Content-Type': 'application/json', 'Transfer-Encoding': 'chunked', 'Date': 'Thu, 10 Apr 2025 07:19:00 GMT', 'Connection': 'close'}
Body: {
  "timestamp": "2025-04-10T07:19:00.942+00:00",
  "status": 400,
  "error": "Bad Request",
  "path": "/send"
}
2025-04-10 10:19:00,944 - __main__ - ERROR - Ошибка при отправке нарушения 145146
2025-04-10 10:19:00,944 - __main__ - WARNING - Не удалось удалить временный файл: name 'tmp_file_path' is not defined
2025-04-10 10:19:00,945 - __main__ - INFO - Обновлена дата последней обработки: 2025-04-10 10:19:00
2025-04-10 10:19:00,945 - app.core.database - INFO - Соединение с PostgreSQL закрыто
2025-04-10 10:19:00,949 - app.core.ftp_client - INFO - FTP соединение закрыто
2025-04-10 10:20:35,196 - app.utils.config_loader - INFO - Успешно загружен F:\замена идпо\RBConverter\conf\connection.json
2025-04-10 10:20:35,196 - app.utils.config_loader - INFO - Успешно загружен F:\замена идпо\RBConverter\conf\configuration.json
2025-04-10 10:20:35,235 - app.core.database - INFO - Успешное подключение к PostgreSQL
2025-04-10 10:20:35,235 - app.core.database - INFO - 2025-02-19 12:00:00
2025-04-10 10:20:35,235 - app.core.database - INFO - Используется start_date: 2025-02-19 12:00:00
2025-04-10 10:20:35,257 - app.core.database - INFO - Найдено нарушений: 1
2025-04-10 10:20:35,258 - __main__ - INFO - Найдено 1 новых нарушений для обработки
2025-04-10 10:20:35,258 - __main__ - INFO - Обработка нарушения 145146 (файл: /mnt/targets/ftp/all_fixations/2025/02/19/2309033_2025_02_19_12_26_42_30_04_00.jpg)
2025-04-10 10:20:35,303 - app.core.ftp_client - INFO - FTP подключение установлено
2025-04-10 10:20:35,505 - app.core.ftp_client - INFO - Загружен файл 2309033_2025_02_19_12_26_42_30_04_00.jpg (1689417 байт)
2025-04-10 10:20:35,582 - app.services.api_service - ERROR - Server error 500: Internal Server Error
Status: 500
Headers: {'Content-Type': 'application/json', 'Transfer-Encoding': 'chunked', 'Date': 'Thu, 10 Apr 2025 07:20:35 GMT', 'Connection': 'close'}
Body: {
  "timestamp": "2025-04-10T07:20:35.579+00:00",
  "status": 500,
  "error": "Internal Server Error",
  "path": "/send"
}
2025-04-10 10:20:35,582 - __main__ - ERROR - Ошибка при отправке нарушения 145146
2025-04-10 10:20:35,582 - __main__ - WARNING - Не удалось удалить временный файл: name 'tmp_file_path' is not defined
2025-04-10 10:20:35,582 - __main__ - INFO - Обновлена дата последней обработки: 2025-04-10 10:20:35
2025-04-10 10:20:35,583 - app.core.database - INFO - Соединение с PostgreSQL закрыто
2025-04-10 10:20:35,588 - app.core.ftp_client - INFO - FTP соединение закрыто
2025-04-10 10:23:38,407 - app.utils.config_loader - INFO - Успешно загружен F:\замена идпо\RBConverter\conf\connection.json
2025-04-10 10:23:38,408 - app.utils.config_loader - INFO - Успешно загружен F:\замена идпо\RBConverter\conf\configuration.json
2025-04-10 10:23:38,446 - app.core.database - INFO - Успешное подключение к PostgreSQL
2025-04-10 10:23:38,446 - app.core.database - INFO - 2025-02-19 12:00:00
2025-04-10 10:23:38,446 - app.core.database - INFO - Используется start_date: 2025-02-19 12:00:00
2025-04-10 10:23:38,470 - app.core.database - INFO - Найдено нарушений: 1
2025-04-10 10:23:38,470 - __main__ - INFO - Найдено 1 новых нарушений для обработки
2025-04-10 10:23:38,470 - __main__ - INFO - Обработка нарушения 145146 (файл: /mnt/targets/ftp/all_fixations/2025/02/19/2309033_2025_02_19_12_26_42_30_04_00.jpg)
2025-04-10 10:23:38,510 - app.core.ftp_client - INFO - FTP подключение установлено
2025-04-10 10:23:38,727 - app.core.ftp_client - INFO - Загружен файл 2309033_2025_02_19_12_26_42_30_04_00.jpg (1689417 байт)
2025-04-10 10:23:38,753 - app.services.api_service - ERROR - Server error 500: Internal Server Error
Status: 500
Headers: {'Content-Type': 'application/json', 'Transfer-Encoding': 'chunked', 'Date': 'Thu, 10 Apr 2025 07:23:38 GMT', 'Connection': 'close'}
Body: {
  "timestamp": "2025-04-10T07:23:38.751+00:00",
  "status": 500,
  "error": "Internal Server Error",
  "path": "/send"
}
2025-04-10 10:23:38,753 - __main__ - ERROR - Ошибка при отправке нарушения 145146
2025-04-10 10:23:38,753 - __main__ - WARNING - Не удалось удалить временный файл: name 'tmp_file_path' is not defined
2025-04-10 10:23:38,754 - __main__ - INFO - Обновлена дата последней обработки: 2025-04-10 10:23:38
2025-04-10 10:23:38,754 - app.core.database - INFO - Соединение с PostgreSQL закрыто
2025-04-10 10:23:38,756 - app.core.ftp_client - INFO - FTP соединение закрыто
2025-04-10 10:26:13,057 - app.utils.config_loader - INFO - Успешно загружен F:\замена идпо\RBConverter\conf\connection.json
2025-04-10 10:26:13,058 - app.utils.config_loader - INFO - Успешно загружен F:\замена идпо\RBConverter\conf\configuration.json
2025-04-10 10:26:13,097 - app.core.database - INFO - Успешное подключение к PostgreSQL
2025-04-10 10:26:13,098 - app.core.database - INFO - 2025-02-19 12:00:00
2025-04-10 10:26:13,099 - app.core.database - INFO - Используется start_date: 2025-02-19 12:00:00
2025-04-10 10:26:13,122 - app.core.database - INFO - Найдено нарушений: 1
2025-04-10 10:26:13,122 - __main__ - INFO - Найдено 1 новых нарушений для обработки
2025-04-10 10:26:13,123 - __main__ - INFO - Обработка нарушения 145146 (файл: /mnt/targets/ftp/all_fixations/2025/02/19/2309033_2025_02_19_12_26_42_30_04_00.jpg)
2025-04-10 10:26:13,169 - app.core.ftp_client - INFO - FTP подключение установлено
2025-04-10 10:26:13,384 - app.core.ftp_client - INFO - Загружен файл 2309033_2025_02_19_12_26_42_30_04_00.jpg (1689417 байт)
2025-04-10 10:26:13,418 - app.services.api_service - ERROR - Server error 500: Internal Server Error
Status: 500
Headers: {'Content-Type': 'application/json', 'Transfer-Encoding': 'chunked', 'Date': 'Thu, 10 Apr 2025 07:26:13 GMT', 'Connection': 'close'}
Body: {
  "timestamp": "2025-04-10T07:26:13.415+00:00",
  "status": 500,
  "error": "Internal Server Error",
  "path": "/send"
}
2025-04-10 10:26:13,418 - __main__ - ERROR - Ошибка при отправке нарушения 145146
2025-04-10 10:26:13,419 - __main__ - WARNING - Не удалось удалить временный файл: name 'tmp_file_path' is not defined
2025-04-10 10:26:13,419 - __main__ - INFO - Обновлена дата последней обработки: 2025-04-10 10:26:13
2025-04-10 10:26:13,420 - app.core.database - INFO - Соединение с PostgreSQL закрыто
2025-04-10 10:26:13,421 - app.core.ftp_client - INFO - FTP соединение закрыто
2025-04-10 10:26:50,662 - app.utils.config_loader - INFO - Успешно загружен F:\замена идпо\RBConverter\conf\connection.json
2025-04-10 10:26:50,663 - app.utils.config_loader - INFO - Успешно загружен F:\замена идпо\RBConverter\conf\configuration.json
2025-04-10 10:26:50,705 - app.core.database - INFO - Успешное подключение к PostgreSQL
2025-04-10 10:26:50,706 - app.core.database - INFO - 2025-02-19 12:00:00
2025-04-10 10:26:50,706 - app.core.database - INFO - Используется start_date: 2025-02-19 12:00:00
2025-04-10 10:26:50,736 - app.core.database - INFO - Найдено нарушений: 1
2025-04-10 10:26:50,736 - __main__ - INFO - Найдено 1 новых нарушений для обработки
2025-04-10 10:26:50,736 - __main__ - INFO - Обработка нарушения 145146 (файл: /mnt/targets/ftp/all_fixations/2025/02/19/2309033_2025_02_19_12_26_42_30_04_00.jpg)
2025-04-10 10:26:50,777 - app.core.ftp_client - INFO - FTP подключение установлено
2025-04-10 10:26:50,983 - app.core.ftp_client - INFO - Загружен файл 2309033_2025_02_19_12_26_42_30_04_00.jpg (1689417 байт)
2025-04-10 10:26:51,006 - app.services.api_service - ERROR - Server error 500: Internal Server Error
Status: 500
Headers: {'Content-Type': 'application/json', 'Transfer-Encoding': 'chunked', 'Date': 'Thu, 10 Apr 2025 07:26:51 GMT', 'Connection': 'close'}
Body: {
  "timestamp": "2025-04-10T07:26:51.002+00:00",
  "status": 500,
  "error": "Internal Server Error",
  "path": "/send"
}
2025-04-10 10:26:51,007 - __main__ - ERROR - Ошибка при отправке нарушения 145146
2025-04-10 10:26:51,007 - __main__ - WARNING - Не удалось удалить временный файл: name 'tmp_file_path' is not defined
2025-04-10 10:26:51,008 - __main__ - INFO - Обновлена дата последней обработки: 2025-04-10 10:26:51
2025-04-10 10:26:51,008 - app.core.database - INFO - Соединение с PostgreSQL закрыто
2025-04-10 10:26:51,013 - app.core.ftp_client - INFO - FTP соединение закрыто
2025-04-10 10:27:53,874 - app.utils.config_loader - INFO - Успешно загружен F:\замена идпо\RBConverter\conf\connection.json
2025-04-10 10:27:53,874 - app.utils.config_loader - INFO - Успешно загружен F:\замена идпо\RBConverter\conf\configuration.json
2025-04-10 10:27:53,905 - app.core.database - INFO - Успешное подключение к PostgreSQL
2025-04-10 10:27:53,905 - app.core.database - INFO - 2025-02-19 12:00:00
2025-04-10 10:27:53,905 - app.core.database - INFO - Используется start_date: 2025-02-19 12:00:00
2025-04-10 10:27:53,926 - app.core.database - INFO - Найдено нарушений: 1
2025-04-10 10:27:53,926 - __main__ - INFO - Найдено 1 новых нарушений для обработки
2025-04-10 10:27:53,926 - __main__ - INFO - Обработка нарушения 145146 (файл: /mnt/targets/ftp/all_fixations/2025/02/19/2309033_2025_02_19_12_26_42_30_04_00.jpg)
2025-04-10 10:27:53,970 - app.core.ftp_client - INFO - FTP подключение установлено
2025-04-10 10:27:54,180 - app.core.ftp_client - INFO - Загружен файл 2309033_2025_02_19_12_26_42_30_04_00.jpg (1689417 байт)
2025-04-10 10:27:54,211 - app.services.api_service - ERROR - Server error 500: Internal Server Error
Status: 500
Headers: {'Content-Type': 'application/json', 'Transfer-Encoding': 'chunked', 'Date': 'Thu, 10 Apr 2025 07:27:54 GMT', 'Connection': 'close'}
Body: {
  "timestamp": "2025-04-10T07:27:54.209+00:00",
  "status": 500,
  "error": "Internal Server Error",
  "path": "/send"
}
2025-04-10 10:27:54,212 - __main__ - ERROR - Ошибка при отправке нарушения 145146
2025-04-10 10:27:54,212 - __main__ - WARNING - Не удалось удалить временный файл: name 'tmp_file_path' is not defined
2025-04-10 10:27:54,212 - __main__ - INFO - Обновлена дата последней обработки: 2025-04-10 10:27:54
2025-04-10 10:27:54,212 - app.core.database - INFO - Соединение с PostgreSQL закрыто
2025-04-10 10:27:54,219 - app.core.ftp_client - INFO - FTP соединение закрыто
2025-04-10 10:33:45,331 - app.utils.config_loader - INFO - Успешно загружен F:\замена идпо\RBConverter\conf\connection.json
2025-04-10 10:33:45,332 - app.utils.config_loader - INFO - Успешно загружен F:\замена идпо\RBConverter\conf\configuration.json
2025-04-10 10:33:45,358 - app.core.database - INFO - Успешное подключение к PostgreSQL
2025-04-10 10:33:45,358 - app.core.database - INFO - 2025-02-19 12:00:00
2025-04-10 10:33:45,358 - app.core.database - INFO - Используется start_date: 2025-02-19 12:00:00
2025-04-10 10:33:45,371 - app.core.database - INFO - Найдено нарушений: 1
2025-04-10 10:33:45,371 - __main__ - INFO - Найдено 1 новых нарушений для обработки
2025-04-10 10:33:45,371 - __main__ - INFO - Обработка нарушения 145146 (файл: /mnt/targets/ftp/all_fixations/2025/02/19/2309033_2025_02_19_12_26_42_30_04_00.jpg)
2025-04-10 10:33:45,405 - app.core.ftp_client - INFO - FTP подключение установлено
2025-04-10 10:33:45,612 - app.core.ftp_client - INFO - Загружен файл 2309033_2025_02_19_12_26_42_30_04_00.jpg (1689417 байт)
2025-04-10 10:33:45,692 - app.services.api_service - INFO - Successfully sent
Status: 200
Headers: {'Content-Length': '0', 'Date': 'Thu, 10 Apr 2025 07:33:45 GMT', 'Keep-Alive': 'timeout=60', 'Connection': 'keep-alive'}
Body: {
  "raw_response": ""
}
2025-04-10 10:33:45,692 - __main__ - INFO - Нарушение 145146 успешно обработано
2025-04-10 10:33:45,692 - __main__ - WARNING - Не удалось удалить временный файл: name 'tmp_file_path' is not defined
2025-04-10 10:33:45,693 - __main__ - INFO - Обновлена дата последней обработки: 2025-04-10 10:33:45
2025-04-10 10:33:45,693 - app.core.database - INFO - Соединение с PostgreSQL закрыто
2025-04-10 10:33:45,698 - app.core.ftp_client - INFO - FTP соединение закрыто
2025-04-10 10:35:23,423 - app.utils.config_loader - INFO - Успешно загружен F:\замена идпо\RBConverter\conf\connection.json
2025-04-10 10:35:23,423 - app.utils.config_loader - INFO - Успешно загружен F:\замена идпо\RBConverter\conf\configuration.json
2025-04-10 10:35:23,466 - app.core.database - INFO - Успешное подключение к PostgreSQL
2025-04-10 10:35:23,466 - app.core.database - INFO - 2025-02-19 12:00:00
2025-04-10 10:35:23,466 - app.core.database - INFO - Используется start_date: 2025-02-19 12:00:00
2025-04-10 10:35:23,488 - app.core.database - INFO - Найдено нарушений: 1
2025-04-10 10:35:23,488 - __main__ - INFO - Найдено 1 новых нарушений для обработки
2025-04-10 10:35:23,488 - __main__ - INFO - Обработка нарушения 145146 (файл: /mnt/targets/ftp/all_fixations/2025/02/19/2309033_2025_02_19_12_26_42_30_04_00.jpg)
2025-04-10 10:35:23,538 - app.core.ftp_client - INFO - FTP подключение установлено
2025-04-10 10:35:23,737 - app.core.ftp_client - INFO - Загружен файл 2309033_2025_02_19_12_26_42_30_04_00.jpg (1689417 байт)
2025-04-10 10:35:23,784 - app.services.api_service - INFO - Successfully sent
Status: 200
Headers: {'Content-Length': '0', 'Date': 'Thu, 10 Apr 2025 07:35:23 GMT', 'Keep-Alive': 'timeout=60', 'Connection': 'keep-alive'}
Body: {
  "raw_response": ""
}
2025-04-10 10:35:23,785 - __main__ - INFO - Нарушение 145146 успешно обработано
2025-04-10 10:35:23,785 - __main__ - INFO - Обновлена дата последней обработки: 2025-04-10 10:35:23
2025-04-10 10:35:23,786 - app.core.database - INFO - Соединение с PostgreSQL закрыто
2025-04-10 10:35:23,787 - app.core.ftp_client - INFO - FTP соединение закрыто
2025-04-10 10:39:52,374 - app.utils.config_loader - INFO - Успешно загружен F:\замена идпо\RBConverter\conf\connection.json
2025-04-10 10:39:52,375 - app.utils.config_loader - INFO - Успешно загружен F:\замена идпо\RBConverter\conf\configuration.json
2025-04-10 10:39:52,421 - app.core.database - INFO - Успешное подключение к PostgreSQL
2025-04-10 10:39:52,421 - app.core.database - INFO - 2025-02-19 12:00:00
2025-04-10 10:39:52,421 - app.core.database - INFO - Используется start_date: 2025-02-19 12:00:00
2025-04-10 10:39:52,435 - app.core.database - INFO - Найдено нарушений: 1
2025-04-10 10:39:52,435 - __main__ - INFO - Найдено 1 новых нарушений для обработки
2025-04-10 10:39:52,435 - __main__ - INFO - Обработка нарушения 145146 (файл: /mnt/targets/ftp/all_fixations/2025/02/19/2309033_2025_02_19_12_26_42_30_04_00.jpg)
2025-04-10 10:39:52,481 - app.core.ftp_client - INFO - FTP подключение установлено
2025-04-10 10:39:52,692 - app.core.ftp_client - INFO - Загружен файл 2309033_2025_02_19_12_26_42_30_04_00.jpg (1689417 байт)
2025-04-10 10:39:52,725 - app.services.api_service - INFO - Successfully sent
Status: 200
Headers: {'Content-Length': '0', 'Date': 'Thu, 10 Apr 2025 07:39:52 GMT', 'Keep-Alive': 'timeout=60', 'Connection': 'keep-alive'}
Body: {
  "raw_response": ""
}
2025-04-10 10:39:52,725 - __main__ - INFO - Нарушение 145146 успешно обработано
2025-04-10 10:39:52,726 - __main__ - INFO - Обновлена дата последней обработки: 2025-04-10 10:39:52
2025-04-10 10:39:52,726 - app.core.database - INFO - Соединение с PostgreSQL закрыто
2025-04-10 10:39:52,728 - app.core.ftp_client - INFO - FTP соединение закрыто
2025-04-10 10:50:54,710 - app.utils.config_loader - INFO - Успешно загружен F:\замена идпо\RBConverter\conf\connection.json
2025-04-10 10:50:54,710 - app.utils.config_loader - INFO - Успешно загружен F:\замена идпо\RBConverter\conf\configuration.json
2025-04-10 10:50:54,757 - app.core.database - INFO - Успешное подключение к PostgreSQL
2025-04-10 10:50:54,757 - app.core.database - INFO - 2025-02-19 12:00:00
2025-04-10 10:50:54,757 - app.core.database - INFO - Используется start_date: 2025-02-19 12:00:00
2025-04-10 10:50:54,779 - app.core.database - INFO - Найдено нарушений: 1
2025-04-10 10:50:54,779 - __main__ - INFO - Найдено 1 новых нарушений для обработки
2025-04-10 10:50:54,779 - __main__ - INFO - Обработка нарушения 145146 (файл: /mnt/targets/ftp/all_fixations/2025/02/19/2309033_2025_02_19_12_26_42_30_04_00.jpg)
2025-04-10 10:50:54,826 - app.core.ftp_client - INFO - FTP подключение установлено
2025-04-10 10:50:55,027 - app.core.ftp_client - INFO - Загружен файл 2309033_2025_02_19_12_26_42_30_04_00.jpg (1689417 байт)
2025-04-10 10:50:55,064 - app.services.api_service - INFO - Successfully sent
Status: 200
Headers: {'Content-Length': '0', 'Date': 'Thu, 10 Apr 2025 07:50:55 GMT', 'Keep-Alive': 'timeout=60', 'Connection': 'keep-alive'}
Body: {
  "raw_response": ""
}
2025-04-10 10:50:55,064 - __main__ - INFO - Нарушение 145146 успешно обработано
2025-04-10 10:50:55,065 - __main__ - INFO - Обновлена дата последней обработки: 2025-04-10 10:50:55
2025-04-10 10:50:55,065 - app.core.database - INFO - Соединение с PostgreSQL закрыто
2025-04-10 10:50:55,067 - app.core.ftp_client - INFO - FTP соединение закрыто
2025-04-10 10:51:33,189 - app.utils.config_loader - INFO - Успешно загружен F:\замена идпо\RBConverter\conf\connection.json
2025-04-10 10:51:33,189 - app.utils.config_loader - INFO - Успешно загружен F:\замена идпо\RBConverter\conf\configuration.json
2025-04-10 10:51:33,257 - app.core.database - INFO - Успешное подключение к PostgreSQL
2025-04-10 10:51:33,257 - app.core.database - INFO - 2025-02-19 12:00:00
2025-04-10 10:51:33,258 - app.core.database - INFO - Используется start_date: 2025-02-19 12:00:00
2025-04-10 10:51:33,274 - app.core.database - INFO - Найдено нарушений: 1
2025-04-10 10:51:33,274 - __main__ - INFO - Найдено 1 новых нарушений для обработки
2025-04-10 10:51:33,274 - __main__ - INFO - Обработка нарушения 145146 (файл: /mnt/targets/ftp/all_fixations/2025/02/19/2309033_2025_02_19_12_26_42_30_04_00.jpg)
2025-04-10 10:51:33,313 - app.core.ftp_client - INFO - FTP подключение установлено
2025-04-10 10:51:33,520 - app.core.ftp_client - INFO - Загружен файл 2309033_2025_02_19_12_26_42_30_04_00.jpg (1689417 байт)
2025-04-10 10:51:33,550 - app.services.api_service - INFO - Successfully sent
Status: 200
Headers: {'Content-Length': '0', 'Date': 'Thu, 10 Apr 2025 07:51:33 GMT', 'Keep-Alive': 'timeout=60', 'Connection': 'keep-alive'}
Body: {
  "raw_response": ""
}
2025-04-10 10:51:33,550 - __main__ - INFO - Нарушение 145146 успешно обработано
2025-04-10 10:51:33,551 - __main__ - INFO - Обновлена дата последней обработки: 2025-04-10 10:51:33
2025-04-10 10:51:33,551 - app.core.database - INFO - Соединение с PostgreSQL закрыто
2025-04-10 10:51:33,552 - app.core.ftp_client - INFO - FTP соединение закрыто
2025-04-10 11:17:47,259 - app.utils.config_loader - INFO - Успешно загружен F:\замена идпо\RBConverter\conf\connection.json
2025-04-10 11:17:47,259 - app.utils.config_loader - INFO - Успешно загружен F:\замена идпо\RBConverter\conf\configuration.json
2025-04-10 11:17:47,297 - app.core.database - INFO - Успешное подключение к PostgreSQL
2025-04-10 11:17:47,297 - app.core.database - INFO - 2025-02-19 12:00:00
2025-04-10 11:17:47,298 - app.core.database - INFO - Используется start_date: 2025-02-19 12:00:00
2025-04-10 11:17:47,321 - app.core.database - INFO - Найдено нарушений: 1
2025-04-10 11:17:47,321 - __main__ - INFO - Найдено 1 новых нарушений для обработки
2025-04-10 11:17:47,321 - __main__ - INFO - Обработка нарушения 145146 (файл: /mnt/targets/ftp/all_fixations/2025/02/19/2309033_2025_02_19_12_26_42_30_04_00.jpg)
2025-04-10 11:17:47,321 - __main__ - ERROR - Ошибка при обработке нарушения 145146: 'FTPClient' object has no attribute 'download'
Traceback (most recent call last):
  File "F:\замена идпо\RBConverter\main.py", line 57, in _process_single_violation
    file_data = self.ftp.download(file_path)
AttributeError: 'FTPClient' object has no attribute 'download'
2025-04-10 11:17:47,322 - __main__ - INFO - Обновлена дата последней обработки: 2025-04-10 11:17:47
2025-04-10 11:17:47,322 - app.core.database - INFO - Соединение с PostgreSQL закрыто
2025-04-10 11:18:02,684 - app.utils.config_loader - INFO - Успешно загружен F:\замена идпо\RBConverter\conf\connection.json
2025-04-10 11:18:02,685 - app.utils.config_loader - INFO - Успешно загружен F:\замена идпо\RBConverter\conf\configuration.json
2025-04-10 11:18:02,722 - app.core.database - INFO - Успешное подключение к PostgreSQL
2025-04-10 11:18:02,722 - app.core.database - INFO - 2025-02-19 12:00:00
2025-04-10 11:18:02,722 - app.core.database - INFO - Используется start_date: 2025-02-19 12:00:00
2025-04-10 11:18:02,745 - app.core.database - INFO - Найдено нарушений: 1
2025-04-10 11:18:02,745 - __main__ - INFO - Найдено 1 новых нарушений для обработки
2025-04-10 11:18:02,745 - __main__ - INFO - Обработка нарушения 145146 (файл: /mnt/targets/ftp/all_fixations/2025/02/19/2309033_2025_02_19_12_26_42_30_04_00.jpg)
2025-04-10 11:18:02,792 - app.core.ftp_client - INFO - FTP подключение установлено
2025-04-10 11:18:02,826 - app.core.jpeg_parser - ERROR - Ошибка при чтении файла: 'dict' object has no attribute 'rfind'
2025-04-10 11:18:02,826 - __main__ - ERROR - Не удалось распарсить данные из файла /mnt/targets/ftp/all_fixations/2025/02/19/2309033_2025_02_19_12_26_42_30_04_00.jpg
2025-04-10 11:18:02,826 - __main__ - INFO - Обновлена дата последней обработки: 2025-04-10 11:18:02
2025-04-10 11:18:02,827 - app.core.database - INFO - Соединение с PostgreSQL закрыто
2025-04-10 11:18:02,831 - app.core.ftp_client - INFO - FTP соединение закрыто
